Workbook

Sheet Summary
A1: DealForge - MVP Tracker (BRD Phase 1)
A2: Source: docs/DealForge_Phase1_BRD Draft.xlsx (88 requirements) | Baseline: main @ 064caee | Date: 26 Sep 2026
A3: Status is evidence-based on code in server/ and src/. Counts are live formulas over Requirements and Backlog.
A5: Requirements by status
A6: Status | B6: Count | C6: % of all
A7: Built | B7: =COUNTIF(Requirements!$F:$F,A7) -> 79 | C7: =IF(COUNTA(Requirements!$A$2:$A$89)=0,0,B7/COUNTA(Requirements!$A$2:$A$89)) -> 0.89772727
A8: Partial | B8: =COUNTIF(Requirements!$F:$F,A8) -> 2 | C8: =IF(COUNTA(Requirements!$A$2:$A$89)=0,0,B8/COUNTA(Requirements!$A$2:$A$89)) -> 0.022727273
A9: Gap | B9: =COUNTIF(Requirements!$F:$F,A9) -> 0 | C9: =IF(COUNTA(Requirements!$A$2:$A$89)=0,0,B9/COUNTA(Requirements!$A$2:$A$89)) -> 0
A10: Deferred | B10: =COUNTIF(Requirements!$F:$F,A10) -> 5 | C10: =IF(COUNTA(Requirements!$A$2:$A$89)=0,0,B10/COUNTA(Requirements!$A$2:$A$89)) -> 0.056818182
A11: Process | B11: =COUNTIF(Requirements!$F:$F,A11) -> 2 | C11: =IF(COUNTA(Requirements!$A$2:$A$89)=0,0,B11/COUNTA(Requirements!$A$2:$A$89)) -> 0.022727273
A12: Total | B12: =SUM(B7:B11) -> 88 | C12: =B12/COUNTA(Requirements!$A$2:$A$89) -> 1
A14: Requirements by priority
A15: Priority | B15: Total | C15: Built | D15: Partial | E15: Gap | F15: Deferred
A16: Must | B16: =COUNTIF(Requirements!$D:$D,A16) -> 65 | C16: =COUNTIFS(Requirements!$D:$D,$A16,Requirements!$F:$F,C15) -> 59 | D16: =COUNTIFS(Requirements!$D:$D,$A16,Requirements!$F:$F,D15) -> 1 | E16: =COUNTIFS(Requirements!$D:$D,$A16,Requirements!$F:$F,E15) -> 0 | F16: =COUNTIFS(Requirements!$D:$D,$A16,Requirements!$F:$F,F15) -> 3
A17: Should | B17: =COUNTIF(Requirements!$D:$D,A17) -> 20 | C17: =COUNTIFS(Requirements!$D:$D,$A17,Requirements!$F:$F,C15) -> 19 | D17: =COUNTIFS(Requirements!$D:$D,$A17,Requirements!$F:$F,D15) -> 1 | E17: =COUNTIFS(Requirements!$D:$D,$A17,Requirements!$F:$F,E15) -> 0 | F17: =COUNTIFS(Requirements!$D:$D,$A17,Requirements!$F:$F,F15) -> 0
A18: Could | B18: =COUNTIF(Requirements!$D:$D,A18) -> 3 | C18: =COUNTIFS(Requirements!$D:$D,$A18,Requirements!$F:$F,C15) -> 1 | D18: =COUNTIFS(Requirements!$D:$D,$A18,Requirements!$F:$F,D15) -> 0 | E18: =COUNTIFS(Requirements!$D:$D,$A18,Requirements!$F:$F,E15) -> 0 | F18: =COUNTIFS(Requirements!$D:$D,$A18,Requirements!$F:$F,F15) -> 2
A19: Total | B19: =SUM(B16:B18) -> 88 | C19: =SUM(C16:C18) -> 79 | D19: =SUM(D16:D18) -> 2 | E19: =SUM(E16:E18) -> 0 | F19: =SUM(F16:F18) -> 5
A21: Backlog by workstream
A22: Workstream | B22: TODOs | C22: Must | D22: Should | E22: Could | F22: Effort (d, est)
A23: W1 Intake | B23: =COUNTIF(Backlog!$B:$B,A23) -> 10 | C23: =COUNTIFS(Backlog!$B:$B,$A23,Backlog!$E:$E,C22) -> 8 | D23: =COUNTIFS(Backlog!$B:$B,$A23,Backlog!$E:$E,D22) -> 1 | E23: =COUNTIFS(Backlog!$B:$B,$A23,Backlog!$E:$E,E22) -> 1 | F23: =SUMIF(Backlog!$B:$B,$A23,Backlog!$L:$L) -> 46
A24: W2 Financials | B24: =COUNTIF(Backlog!$B:$B,A24) -> 10 | C24: =COUNTIFS(Backlog!$B:$B,$A24,Backlog!$E:$E,C22) -> 9 | D24: =COUNTIFS(Backlog!$B:$B,$A24,Backlog!$E:$E,D22) -> 1 | E24: =COUNTIFS(Backlog!$B:$B,$A24,Backlog!$E:$E,E22) -> 0 | F24: =SUMIF(Backlog!$B:$B,$A24,Backlog!$L:$L) -> 48
A25: W3 Screening | B25: =COUNTIF(Backlog!$B:$B,A25) -> 13 | C25: =COUNTIFS(Backlog!$B:$B,$A25,Backlog!$E:$E,C22) -> 8 | D25: =COUNTIFS(Backlog!$B:$B,$A25,Backlog!$E:$E,D22) -> 5 | E25: =COUNTIFS(Backlog!$B:$B,$A25,Backlog!$E:$E,E22) -> 0 | F25: =SUMIF(Backlog!$B:$B,$A25,Backlog!$L:$L) -> 72
A26: W4 Entity | B26: =COUNTIF(Backlog!$B:$B,A26) -> 4 | C26: =COUNTIFS(Backlog!$B:$B,$A26,Backlog!$E:$E,C22) -> 4 | D26: =COUNTIFS(Backlog!$B:$B,$A26,Backlog!$E:$E,D22) -> 0 | E26: =COUNTIFS(Backlog!$B:$B,$A26,Backlog!$E:$E,E22) -> 0 | F26: =SUMIF(Backlog!$B:$B,$A26,Backlog!$L:$L) -> 17
A27: W5 Documents | B27: =COUNTIF(Backlog!$B:$B,A27) -> 5 | C27: =COUNTIFS(Backlog!$B:$B,$A27,Backlog!$E:$E,C22) -> 2 | D27: =COUNTIFS(Backlog!$B:$B,$A27,Backlog!$E:$E,D22) -> 3 | E27: =COUNTIFS(Backlog!$B:$B,$A27,Backlog!$E:$E,E22) -> 0 | F27: =SUMIF(Backlog!$B:$B,$A27,Backlog!$L:$L) -> 27
A28: W6 Governance | B28: =COUNTIF(Backlog!$B:$B,A28) -> 7 | C28: =COUNTIFS(Backlog!$B:$B,$A28,Backlog!$E:$E,C22) -> 6 | D28: =COUNTIFS(Backlog!$B:$B,$A28,Backlog!$E:$E,D22) -> 1 | E28: =COUNTIFS(Backlog!$B:$B,$A28,Backlog!$E:$E,E22) -> 0 | F28: =SUMIF(Backlog!$B:$B,$A28,Backlog!$L:$L) -> 23
A29: W7 Reporting | B29: =COUNTIF(Backlog!$B:$B,A29) -> 5 | C29: =COUNTIFS(Backlog!$B:$B,$A29,Backlog!$E:$E,C22) -> 2 | D29: =COUNTIFS(Backlog!$B:$B,$A29,Backlog!$E:$E,D22) -> 3 | E29: =COUNTIFS(Backlog!$B:$B,$A29,Backlog!$E:$E,E22) -> 0 | F29: =SUMIF(Backlog!$B:$B,$A29,Backlog!$L:$L) -> 31
A30: W8 Platform | B30: =COUNTIF(Backlog!$B:$B,A30) -> 6 | C30: =COUNTIFS(Backlog!$B:$B,$A30,Backlog!$E:$E,C22) -> 3 | D30: =COUNTIFS(Backlog!$B:$B,$A30,Backlog!$E:$E,D22) -> 3 | E30: =COUNTIFS(Backlog!$B:$B,$A30,Backlog!$E:$E,E22) -> 0 | F30: =SUMIF(Backlog!$B:$B,$A30,Backlog!$L:$L) -> 34
A31: W9 NFR/Release | B31: =COUNTIF(Backlog!$B:$B,A31) -> 8 | C31: =COUNTIFS(Backlog!$B:$B,$A31,Backlog!$E:$E,C22) -> 5 | D31: =COUNTIFS(Backlog!$B:$B,$A31,Backlog!$E:$E,D22) -> 3 | E31: =COUNTIFS(Backlog!$B:$B,$A31,Backlog!$E:$E,E22) -> 0 | F31: =SUMIF(Backlog!$B:$B,$A31,Backlog!$L:$L) -> 25
A32: Total | B32: =SUM(B23:B31) -> 68 | C32: =SUM(C23:C31) -> 47 | D32: =SUM(D23:D31) -> 20 | E32: =SUM(E23:E31) -> 1 | F32: =SUM(F23:F31) -> 323
A34: Slices
A35: S0 | B35: W0 | C35: Reconcile & freeze
A36: S1 | B36: W1-W3 | C36: Intake governance
A37: S2 | B37: W3-W6 | C37: Financials & returns
A38: S3 | B38: W5-W8 | C38: Screening & scorecard
A39: S4 | B39: W6-W8 | C39: Entity, docs & templates
A40: S5 | B40: W8-W10 | C40: Governance & audit hardening
A41: S6 | B41: W9-W11 | C41: Reporting & output
A42: S7 | B42: W10-W12 | C42: Platform, auth & config
A43: S8 | B43: W12-W13 | C43: Hardening & NFR
A44: S9 | B44: W13-W14 | C44: UAT & sign-off
...

Sheet Requirements
A1: Req ID | B1: Module | C1: Requirement | D1: Priority | E1: Phase | F1: Status | G1: Workstream | H1: Mapped TODO | I1: Evidence / Gap
A2: PLT-01 | B2: Platform & Access | C2: Multi-organisation hierarchy | D2: Must | E2: Phase 1 | F2: Built | G2: Platform | I2: server/org.js, orgApi.js, GroupStructure.jsx; tests m1
A3: PLT-02 | B3: Platform & Access | C3: Entity-based data isolation | D3: Must | E3: Phase 1 | F3: Built | G3: Platform | I3: server/abac.js (CROSS_ORG_READ_ROLES, canRead); m1/m5
A4: PLT-03 | B4: Platform & Access | C4: Role-based access control | D4: Must | E4: Phase 1 | F4: Built | G4: Platform | I4: server/rbac.js (14 roles, ACTION_ROLES)
A5: PLT-04 | B5: Platform & Access | C5: Single sign-on + MFA | D5: Must | E5: Phase 1 | F5: Built | G5: W8 Platform | H5: W8-01 | I5: SSO (OIDC/SAML) + MFA; local accounts for externals. See Backlog W8-01. Evidence: docs/evidence/W8-01/
A6: PLT-05 | B6: Platform & Access | C6: User administration | D6: Must | E6: Phase 1 | F6: Built | G6: W8 Platform | H6: W8-06 | I6: User administration hardening: deactivation is immediate (inactive/banned accounts resolve to no actor and lose their live sessions) and every lifecycle action is named and audited (server/config/userAdmin.js + server/users.js + server/admin.js + SuperAdmin.jsx). Evidence: docs/evidence/W8-06/
A7: PLT-06 | B7: Platform & Access | C7: Bilingual-ready interface | D7: Should | E7: Phase 1 | F7: Built | G7: W8 Platform | H7: W8-02 | I7: i18n completion: all core UI strings externalised; RTL demonstrated on Dashboard. See Backlog W8-02. Evidence: docs/evidence/W8-02/
A8: ENT-01 | B8: Entity & Strategy Library | C8: Entity strategy profile | D8: Must | E8: Phase 1 | F8: Built | G8: W4 Entity | H8: W4-03 | I8: server/strategy.js screening_record profile version; docs/evidence/W4-03/
A9: ENT-02 | B9: Entity & Strategy Library | C9: Strategy document upload | D9: Must | E9: Phase 1 | F9: Built | G9: W4 Entity | H9: W4-02 | I9: server/strategy.js indexing + citation; docs/evidence/W4-02/
A10: ENT-03 | B10: Entity & Strategy Library | C10: Sirius group mandate | D10: Must | E10: Phase 1 | F10: Built | G10: W4 Entity | H10: W4-04 | I10: server/config/siriusMandate.js + server/mandate.js (versioned group mandate); docs/evidence/W4-04/
A11: ENT-04 | B11: Entity & Strategy Library | C11: Portfolio register | D11: Must | E11: Phase 1 | F11: Built | G11: W4 Entity | H11: W4-01 | I11: docs/evidence/W4-01/
A12: INT-01 | B12: Opportunity Intake | C12: Single controlled intake channel | D12: Must | E12: Phase 1 | F12: Built | G12: W1 Intake | I12: SubmitOpportunity.jsx, pipeline.js
A13: INT-02 | B13: Opportunity Intake | C13: Self-screen before drafting | D13: Must | E13: Phase 1 | F13: Built | G13: W1 Intake | H13: W1-01 | I13: server/config/selfScreen.js six-question screen + evaluateSelfScreen; gate.js POST /api/gate/self-screen and submit 422 block; SubmitOpportunity.jsx pre-form step with stop messages; selfscreen.test.js (12 pass). Evidence: docs/evidence/W1-01/
A14: INT-03 | B14: Opportunity Intake | C14: Below-floor exception route | D14: Must | E14: Phase 1 | F14: Built | G14: W1 Intake | H14: W1-02 | I14: server/config/belowFloor.js evaluateBelowFloor (synergy + IRR>=35% + Sirius escalation) folded into selfScreen.js and gate.js; submit 422 block, below-floor tag persisted and escalated (notify deliver:false), pipeline_transition comment; SubmitOpportunity.jsx route alerts; belowFloor.test.js (6 pass), m2.test.js W1-02 (3 pass). Evidence: docs/evidence/W1-02/
A15: INT-04 | B15: Opportunity Intake | C15: Opportunity type classification | D15: Must | E15: Phase 1 | F15: Built | G15: W1 Intake | I15: opportunity_type in OPPORTUNITY_FIELDS (gate.js)
A16: INT-05 | B16: Opportunity Intake | C16: Sourcing channel | D16: Must | E16: Phase 1 | F16: Built | G16: W1 Intake | H16: W1-08 | I16: server/config/sourcingChannel.js side-effects (mandatory channel; IHC/affiliate auto related-party flag; banker/advisor compressed-timeline indicator); gate.js sourcing_channel in evaluateGate + /fields + submit 422 block and persistence; siriusMemo sourcing key fact + side-effects note; SubmitOpportunity.jsx alerts; sourcingChannel.test.js (8 pass), m2.test.js W1-08 (5 pass); evidence docs/evidence/W1-08
A17: INT-06 | B17: Opportunity Intake | C17: Structured Opportunity Overview form (6 sections) | D17: Must | E17: Phase 1 | F17: Built | G17: W1 Intake | H17: W1-03 | I17: server/config/intakeConfig.js six-section model; gate.js GET /api/gate/fields; SubmitOpportunity.jsx renders model; intake.test.js
A18: INT-07 | B18: Opportunity Intake | C18: Accretion Statement | D18: Must | E18: Phase 1 | F18: Built | G18: W1 Intake | H18: W1-04 | I18: accretion fields in intakeConfig.js; rendered in memo (siriusMemoDocx.js); intake.test.js
A19: INT-08 | B19: Opportunity Intake | C19: Qualifying gates checklist (10 gates) | D19: Must | E19: Phase 1 | F19: Built | G19: W1 Intake | H19: W1-05 | I19: 10-gate checklist in server/config/qualifyingGates.js; blocking 422 on any No in server/gate.js submit route; SubmitOpportunity.jsx qualifying-gates card; qualifyingGates.test.js; evidence docs/evidence/W1-05
A20: INT-09 | B20: Opportunity Intake | C20: CEO and CFO attestation | D20: Must | E20: Phase 1 | F20: Built | G20: W1 Intake | H20: W1-06 | I20: server/config/attestations.js (ceo/cfo + subsidiary role specs, configurable attestation_text setting); gate.js loadAttestationTexts/evaluateGate attestations + POST /opportunities/:id/attestations/:key + submit 422 block (attestation_recorded / submit_blocked audits); SubmitOpportunity.jsx attestation card; attestations.test.js (8 pass), m2.test.js W1-06 (4 pass); evidence docs/evidence/W1-06
A21: INT-10 | B21: Opportunity Intake | C21: Greenfield extra tests | D21: Must | E21: Phase 1 | F21: Built | G21: W1 Intake | H21: W1-07 | I21: server/config/greenfield.js extra tests (stage Concept/Feasibility/Initiate, quantified benefit, thesis, budget, secured funding source; Concept capped at a 2-page note); gate.js greenfield in evaluateGate (Concept waives the full pack) + submit 422 block (greenfield_stops audit); SubmitOpportunity.jsx alerts; greenfield.test.js (9 pass), m2.test.js W1-07 (4 pass); evidence docs/evidence/W1-07
A22: INT-11 | B22: Opportunity Intake | C22: Related-party disclosure | D22: Must | E22: Phase 1 | F22: Built | G22: W1 Intake | I22: relatedParty.js flag + independent reviewer routing
A23: INT-12 | B23: Opportunity Intake | C23: Duplicate detection | D23: Could | E23: Phase 1 | F23: Built | G23: W1 Intake | H23: W1-10 | I23: duplicates.js + config/duplicates.js cross-group match warning with link/dismiss decisions in duplicate_review, Investment-Team-only (403 for the preparer, subsidiary isolation preserved); duplicates.test.js (8 pass), m3.test.js W1-10 (3 pass); evidence docs/evidence/W1-10
A24: INT-13 | B24: Opportunity Intake | C24: Withdraw submission | D24: Should | E24: Phase 1 | F24: Built | G24: W1 Intake | H24: W1-09 | I24: pipeline.js withdrawn state + reason-required withdraw transition retained in pipeline_transition history and on the opportunity (withdrawn_reason/withdrawn_at); board Withdrawn column; m3.test.js W1-09 (4 pass); evidence docs/evidence/W1-09
A25: DOC-01 | B25: Documents & Completeness | C25: Document checklist by type/stage/flags | D25: Must | E25: Phase 1 | F25: Built | G25: W5 Documents | H25: W5-01 | I25: docs/evidence/W5-01/
A26: DOC-02 | B26: Documents & Completeness | C26: Document upload and storage | D26: Must | E26: Phase 1 | F26: Built | G26: W5 Documents | H26: W5-02 | I26: docs/evidence/W5-02/
A27: DOC-03 | B27: Documents & Completeness | C27: Mandatory-document gate | D27: Must | E27: Phase 1 | F27: Built | G27: W5 Documents | I27: evaluateGate, SUBMITTABLE_STATES; tests m2
A28: DOC-04 | B28: Documents & Completeness | C28: Content sufficiency check | D28: Should | E28: Phase 1 | F28: Built | G28: W5 Documents | H28: W5-03 | I28: docs/evidence/W5-03/
A29: DOC-05 | B29: Documents & Completeness | C29: Data-point to source mapping | D29: Should | E29: Phase 1 | F29: Built | G29: W5 Documents | H29: W5-04 | I29: docs/evidence/W5-04/
A30: DOC-06 | B30: Documents & Completeness | C30: Document templates | D30: Should | E30: Phase 1 | F30: Built | G30: W5 Documents | H30: W5-05 | I30: docs/evidence/W5-05/
A31: FIN-01 | B31: Financials & Returns | C31: Financial summary capture (FY-3 to Y+5) | D31: Must | E31: Phase 1 | F31: Built | G31: W2 Financials | H31: W2-01 | I31: server/config/financials.js 8-row x 8-period Part B p.4 matrix with derived growth %/EBITDA margin %/FCF/net debt-EBITDA; SubmitOpportunity.jsx editable grid; siriusMemo.js + SiriusMemoDialog finTable; new-venture actuals optional. Evidence: docs/evidence/W2-01/
A32: FIN-02 | B32: Financials & Returns | C32: Three-statement model upload and check | D32: Must | E32: Phase 1 | F32: Built | G32: W2 Financials | H32: W2-02 | I32: server/config/statementModel.js parses the linked three-statement model (CSV/TSV/JSON, dependency-free) and checks presence of P&L + balance sheet + cash flow and the per-period balance-sheet equality (tolerance env-configurable). Registration on the mandatory financials upload; server/gate.js persists statement_model + audit; advisory flags (non-template / unbalanced / missing) never block a submission. SubmitOpportunity.jsx 4b advisory card; sample fixtures carry balanced, projections-only and unbalanced models. Evidence: docs/evidence/W2-02/
A33: FIN-03 | B33: Financials & Returns | C33: Return metrics under three scenarios | D33: Must | E33: Phase 1 | F33: Built | G33: W2 Financials | H33: W2-03 | I33: server/config/returnMetrics.js captures Equity IRR, ROIC and payback for base/upside/downside (all mandatory) and MOIC where relevant; evaluateReturnMetrics flags a missing downside and open cells without blocking. server/gate.js return_metrics on evaluateGate + returns config on GET /api/gate/fields; siriusMemo.js fills the page-4 returns table from the flat fields; SubmitOpportunity.jsx 4c advisory card. Evidence: docs/evidence/W2-03/
A34: FIN-04 | B34: Financials & Returns | C34: Automatic hurdle test | D34: Must | E34: Phase 1 | F34: Built | G34: W2 Financials | H34: W2-04 | I34: server/config/hurdleTable.js evaluates every hurdle per captured scenario (Equity IRR >= 20%/greenfield 25%, ROIC >= WACC+5%, payback <= 3.5yrs, concentration <= 35%, leverage <= 3x) with a version stamp (HURDLE_TABLE_VERSION); thresholds come from mandate_threshold so an admin change moves the verdicts. server/gate.js hurdle_table on evaluateGate + GET /api/gate/fields; GET /api/themes/hurdles exposes the org policy; siriusMemo.js prints the live thresholds, per-scenario Meets? and a policy note; SubmitOpportunity.jsx 4e advisory card. Evidence: docs/evidence/W2-04/
A35: FIN-05 | B35: Financials & Returns | C35: WACC input | D35: Must | E35: Phase 1 | F35: Built | G35: W2 Financials | H35: W2-05 | I35: server/config/wacc.js resolves the effective WACC (entity default from mandate_threshold.wacc_pct, env-overridable shipped default, or a reasoned per-opportunity override); an override without a reason is flagged override_valid:false and never applied silently. server/gate.js wacc on evaluateGate + config on GET /api/gate/fields; ThemeAdmin sets the entity WACC; SubmitOpportunity.jsx 4d card. Evidence: docs/evidence/W2-05/
A36: FIN-06 | B36: Financials & Returns | C36: Financial sources and uses | D36: Must | E36: Phase 1 | F36: Built | G36: W2 Financials | H36: W2-06 | I36: server/config/sourcesUses.js captures each source (internal accruals, subsidiary debt, partner / co-investor, Sirius capital) with amount, % of total and status (secured/committed/indicative) and each use (purchase price, transaction costs, working capital, contingency); sources must equal uses (within a configurable tolerance) and Sirius capital is warned when drawn ahead of cheaper sources. server/gate.js sources_uses + GET /api/gate/fields; siriusMemo.js funding tables + balance note; SubmitOpportunity.jsx 5a card. Evidence: docs/evidence/W2-06/
A37: FIN-07 | B37: Financials & Returns | C37: Budget status | D37: Must | E37: Phase 1 | F37: Built | G37: W2 Financials | H37: W2-07 | I37: server/config/budgetStatus.js confirms whether the opportunity is in the approved budget; off-budget requires a variance justification and makes a variance-memo upload (budget_confirmation) mandatory before submission, while an in-budget line reference is advisory. server/gate.js budget_status + submit-route block; siriusMemo.js budget note; SubmitOpportunity.jsx 5b card. Evidence: docs/evidence/W2-07/
A38: FIN-08 | B38: Financials & Returns | C38: Cross-border considerations | D38: Should | E38: Phase 1 | F38: Built | G38: W2 Financials | H38: W2-09 | I38: server/config/crossBorder.js captures FX exposure, withholding tax, transfer pricing and repatriation restrictions for cross-border deals; the block applies only when the target geography names a different country from the owning subsidiary’s registered geography (canonicalCountry / isCrossBorder via GEOGRAPHY_TAGS), so a domestic deal is never asked. server/gate.js cross_border + GET /api/gate/fields; siriusMemo.js conditional Cross-border considerations table; SubmitOpportunity.jsx 4c card. Evidence: docs/evidence/W2-09/
A39: FIN-09 | B39: Financials & Returns | C39: Entry valuation and exit | D39: Must | E39: Phase 1 | F39: Built | G39: W2 Financials | H39: W2-08 | I39: server/config/valuation.js captures the entry valuation as structured fields (EV / equity basis, amount, multiple, method) with a 3-5 name comparable set (nested valuation_comparables) and the exit / value-realisation route, timing and target multiple; a partial capture raises advisory flags (missing basis/method, comparable set below 3 or above 5, exit route without timing) and never blocks. server/gate.js valuation + GET /api/gate/fields; siriusMemo.js prints the comparable table and the entry/exit notes; SubmitOpportunity.jsx 4b card. Evidence: docs/evidence/W2-08/
A40: FIN-10 | B40: Financials & Returns | C40: Deeper investment analytics | D40: Could | E40: Later phase | F40: Deferred | I40: BRD = Later phase
...

Sheet Backlog
A1: TODO ID | B1: Workstream | C1: Title | D1: BRD Req(s) | E1: Priority | F1: Size | G1: Slice | H1: Depends on | I1: Owner | J1: Acceptance criteria | K1: Status | L1: Effort (d) | M1: Evidence
A2: W1-01 | B2: W1 Intake | C2: Pre-form self-screen step (type, commitment, sector, geography, in-plan, related party) with stop messages | D2: INT-02 | E2: Must | F2: M | G2: S1 | I2: Intake squad | J2: Out-of-appetite types stop with reason; commitment < AED 10mn stops unless exception chosen | K2: Done | L2: 5 | M2: code: server/config/selfScreen.js (six questions + evaluateSelfScreen, configured stops/flags/messages); server/gate.js GET /api/gate/fields self_screen, POST /api/gate/self-screen, submit blocked 422 + submit_blocked audit; src/pages/SubmitOpportunity.jsx pre-form self-screen step with locked capture form; src/api/client.js gate.selfScreen. test: server/tests/selfscreen.test.js (12 pass); server/tests/m2.test.js W1-01 gate block (18 pass). Evidence: docs/evidence/W1-01/preparer_self_screen_stop.png, docs/evidence/W1-01/preparer_self_screen_pass.png
A3: W1-02 | B3: W1 Intake | C3: Below-floor exception route (synergy statement + IRR >= 35%), tagged and Sirius-escalated | D3: INT-03 | E3: Must | F3: M | G3: S1 | H3: W1-01 | I3: Intake squad | J3: Exception requires both fields; case cannot close at subsidiary level | K3: Done | L3: 5 | M3: code: server/config/belowFloor.js (BELOW_FLOOR_TAG/FIELDS/MESSAGES, BELOW_FLOOR_ESCALATION to Sirius, isBelowFloor, evaluateBelowFloor); selfScreen.js folds below_floor into the pre-form result; gate.js evaluateGate below_floor + submit 422 block (submit_blocked audit) + tagging (below_floor_exception/tag/escalated/escalated_at), pipeline_transition comment and notify below_floor_escalation to deal.lead@sirius.local; intakeConfig.js below_floor_synergy_case field; SubmitOpportunity.jsx below-floor-route / below-floor-tagged alerts; mvpSeed.js seed-below-floor + seed-below-floor-incomplete fixtures. test: server/tests/belowFloor.test.js (6 pass); server/tests/m2.test.js W1-02 route (3 pass, 21 total); full suite 177 pass. Evidence: docs/evidence/W1-02/preparer_below_floor_tagged.png, preparer_below_floor_route_incomplete.png, preparer_below_floor_submit_blocked.png
A4: W1-03 | B4: W1 Intake | C4: Extend OPPORTUNITY_FIELDS to the six Opportunity Overview sections with per-section progress | D4: INT-06 | E4: Must | F4: L | G4: S1 | I4: Intake squad | J4: All six sections in fixed order; completion indicator per section; save-as-draft | K4: Done | L4: 10 | M4: code: server/config/intakeConfig.js (6 sections, ~50 fields); server/gate.js OPPORTUNITY_FIELDS + GET /api/gate/fields; src/pages/SubmitOpportunity.jsx renders the model with per-section completion indicators (fixed group.key lookup). test: server/tests/intake.test.js (9 pass); commit 064caee. Evidence: docs/evidence/W1-03/preparer_six_section_form.png
A5: W1-04 | B5: W1 Intake | C5: Accretion Statement structured mandatory fields | D5: INT-07 | E5: Must | F5: S | G5: S1 | H5: W1-03 | I5: Intake squad | J5: Fields mandatory; rendered in screening memo | K5: Done | L5: 2 | M5: code: intakeConfig.js accretion fields + OVERVIEW_SECTIONS.accretion; rendered in memo (server/siriusMemoDocx.js); test: server/tests/intake.test.js accretion case; commit 064caee. Evidence: docs/evidence/W1-04/preparer_accretion_statement.png
A6: W1-05 | B6: W1 Intake | C6: Ten qualifying gates checklist, each Yes + evidence link, blocking submission on any No | D6: INT-08 | E6: Must | F6: M | G6: S1 | H6: W1-03 | I6: Intake squad | J6: No blocks submission; evidence link required per gate | K6: Done | L6: 5 | M6: code: server/config/qualifyingGates.js (10 BRD-ordered gates, evaluateQualifyingGates, gateAnswerKey); server/gate.js qualifying_gates in evaluateGate + /fields + submit-route 422 block (QUALIFYING_GATE_NOT_READY); UI http://.../ submit form qualifying-gates card with per-gate Yes/No + evidence ticks; test: server/tests/qualifyingGates.test.js (7); seed fixture seed-qualifying-no; Evidence: docs/evidence/W1-05/preparer_qualifying_gates_all_ready.png, preparer_qualifying_gate_no_blocked.png, preparer_qualifying_gate_submit_blocked.png
A7: W1-06 | B7: W1 Intake | C7: CEO + CFO attestation gate (two named attestations, timestamp + IP, configurable text) | D7: INT-09 | E7: Must | F7: M | G7: S1 | I7: Intake squad | J7: Submission impossible until both recorded; each on audit log | K7: Done | L7: 5 | M7: code: server/config/attestations.js (ATTESTATION_ROLES ceo/cfo + subsidiary variants, configurable ATTESTATION_SETTING_KEY='attestation_text' with DEFAULT_ATTESTATION_TEXTS, pure evaluateAttestations requiring by+at per role, attestationDefaults seed helper); server/gate.js loadAttestationTexts() reads AppSettings attestation_text, evaluateGate returns attestations, GET /api/gate/fields exposes attestations[], new POST /api/opportunities/:id/attestations/:key (role-authorized + canWriteOrg, draft/returned only, stores by/name/role/at/ip/text, audit attestation_recorded), submit route 422 block with ATTESTATION_REQUIRED_MESSAGE + submit_blocked audit; src/pages/SubmitOpportunity.jsx CEO & CFO attestation card with per-role signing; src/api/client.js gate.attest; mvpSeed.js fullFields attestations + seed-attestation-missing fixture (13 total). test: server/tests/attestations.test.js (8 pass); server/tests/m2.test.js W1-06 (4 pass, 25 total); full suite 198 pass; seedCleanup 5 pass. Evidence: docs/evidence/W1-06/preparer_attestations_all_ready.png, preparer_attestation_one_signed.png, preparer_attestation_submit_blocked.png
A8: W1-07 | B8: W1 Intake | C8: Greenfield extra tests (benefit/why-now, budget status, secured funding, stage Concept/Feasibility/Initiate) | D8: INT-10 | E8: Must | F8: M | G8: S1 | H8: W1-03 | I8: Intake squad | J8: Greenfield without secured funding blocked; Concept allows 2-page concept note only | K8: Done | L8: 5 | M8: code: server/config/greenfield.js (GREENFIELD_STAGES Concept/Feasibility/Initiate, GREENFIELD_FIELDS greenfield_stage/benefit/secured_funding_source, GREENFIELD_THESIS_FIELDS, CONCEPT_NOTE_MAX_PAGES=2, pure evaluateGreenfield requiring stage + benefit + thesis + budget + a named SECURED source, greenfieldDefaults); server/config/intakeConfig.js greenfield_stage/benefit/secured_funding_source fields; server/gate.js evaluateGate greenfield (waives the document pack at Concept) + GET /api/gate/fields greenfield stages + submit-route 422 block (GREENFIELD_NOT_READY, submit_blocked audit); src/pages/SubmitOpportunity.jsx greenfield-tests / greenfield-tests-ready alerts; mvpSeed.js seed-greenfield (Concept, cleared) + seed-greenfield-unfunded (Feasibility, blocked), 14 fixtures. test: server/tests/greenfield.test.js (9 pass); server/tests/m2.test.js W1-07 (4 pass, 29 total); full suite 211 pass; seedCleanup 5 pass. Evidence: docs/evidence/W1-07/preparer_greenfield_tests_incomplete.png, preparer_greenfield_tests_ready.png, preparer_greenfield_submit_blocked.png
A9: W1-08 | B9: W1 Intake | C9: Sourcing-channel side-effects: IHC/affiliate auto related-party flag; banker-led compressed-timeline indicator | D9: INT-05 | E9: Must | F9: S | G9: S1 | I9: Intake squad | J9: Flags auto-set and shown on every screen/output | K9: Done | L9: 2 | M9: code: server/config/sourcingChannel.js (SOURCING_CHANNEL_FIELD, COMPRESSED_TIMELINE_CHANNEL/COMPRESSED_TIMELINE_TAG, RELATED_PARTY_TAG, pure evaluateSourcingChannel - mandatory channel, IHC/affiliate auto related-party flag via related_by_default, banker/advisor compressed-timeline indicator); server/gate.js sourcing_channel in evaluateGate + GET /api/gate/fields channels, submit 422 block on a missing/unrecognised channel, submit persists sourcing_tags + related_party_auto_flag + compressed_timeline; server/config/siriusMemo.js 'Sourcing channel' key fact + 'Sourcing side-effects' note; src/pages/SubmitOpportunity.jsx sourcing-channel-effects / sourcing-channel-required alerts; mvpSeed.js seed-banker-led fixture, 15 fixtures. test: server/tests/sourcingChannel.test.js (8 pass); server/tests/m2.test.js W1-08 (5 pass, 34 total); full suite 224 pass. Evidence: docs/evidence/W1-08/preparer_sourcing_affiliate_related_party.png, preparer_sourcing_banker_compressed_timeline.png
A10: W1-09 | B10: W1 Intake | C10: Withdraw submission with reason; retained in history | D10: INT-13 | E10: Should | F10: S | G10: S1 | I10: Intake squad | J10: Withdrawn visible in history with reason | K10: Done | L10: 2 | M10: code: server/pipeline.js withdrawn state (TRANSITIONS submission/returned to withdrawn), transition() requires a reason and records withdrawn_reason/withdrawn_at/withdrawn_by, opportunityToCard exposes withdrawn_reason + can_withdraw, board adds a Withdrawn column and my-opportunities excludes withdrawn from open; src/pages/ScreeningBoard.jsx Withdrawn column, reason-required dialog, withdraw offered only where can_withdraw. test: server/tests/m3.test.js W1-09 (4 pass). Evidence: docs/evidence/W1-09/preparer_withdraw_reason_dialog.png, preparer_withdrawn_in_history.png
A11: W1-10 | B11: W1 Intake | C11: Duplicate detection warning to Investment Team (link/dismiss) | D11: INT-12 | E11: Could | F11: M | G11: S1 | I11: Intake squad | J11: Warns Investment Team only; subsidiary isolation preserved | K11: Done | L11: 5 | M11: code: server/config/duplicates.js pure findDuplicates/compareOpportunities (same target/counterparty or similar name); server/duplicates.js /api/duplicates routes (Investment-Team-only) with duplicate_review link/dismiss, db.js duplicate_review table; pipeline.js board attaches duplicate_warning for cross-org readers only; src/api/client.js duplicates API; ScreeningBoard.jsx duplicate panel with link/dismiss; mvpSeed.js seed-duplicate-finstreet fixture. test: server/tests/duplicates.test.js (8 pass); server/tests/m3.test.js W1-10 (3 pass). Evidence: docs/evidence/W1-10/analyst_duplicate_warning.png, analyst_duplicate_dismissed.png
A12: W2-01 | B12: W2 Financials | C12: Financial summary table FY-3..FY-1 + Y1-Y5 with derived ratios | D12: FIN-01 | E12: Must | F12: L | G12: S2 | H12: W1-03 | I12: Financials squad | J12: Matches Part B p.4 layout; ratios auto-calculated; new ventures may leave actuals blank | K12: Done | L12: 10 | M12: code: server/config/financials.js (FINANCIAL_PERIODS/ROWS, deriveFinancials, evaluateFinancials, isNewVenture); server/config/siriusMemo.js finTable from deriveFinancials; server/gate.js expose financials + evaluate on GET /api/gate/fields; src/pages/SubmitOpportunity.jsx financial grid (data-testid=financial-grid, fin-<row>-<period>); src/components/pipeline/SiriusMemoDialog.jsx memo-fin-table; mvpSeed.js seed-inf-vision matrix + greenfieldFinancials() for seed-greenfield. test: server/tests/financials.test.js (12 pass); siriusMemo.test.js finTable. Evidence: docs/evidence/W2-01/preparer_financial_summary_grid.png, preparer_financial_greenfield_blank_actuals.png, analyst_memo_financial_summary.png
A13: W2-02 | B13: W2 Financials | C13: Three-statement model upload + presence/balance check | D13: FIN-02 | E13: Must | F13: L | G13: S2 | H13: W2-01 | I13: Financials squad | J13: Missing statement / unbalanced BS raises flag; non-template flagged for manual review | K13: Done | L13: 10 | M13: code: server/config/statementModel.js (THREE_STATEMENTS, BALANCE_SHEET_TOTALS, BALANCE_TOLERANCE_PCT, parseStatementModel, evaluateStatementModel, statementTemplateCsv); server/gate.js parse financials upload -> persist statement_model + statement_model_parsed audit + evaluateGate/GET /api/gate/fields; src/pages/SubmitOpportunity.jsx advisory 4b card (data-testid=statement-model-card, statement-model-status, statement-model-<key>, statement-model-balance, statement-model-flag/ok); server/config/mvpSeed.js balanced/greenfield/unbalanced models on fixtures. test: server/tests/statementModel.test.js (13 pass); server/tests/m2.test.js FIN-02 cases (template complete, unbalanced accepted+flagged, non-template accepted+flagged, parse audited). Evidence: docs/evidence/W2-02/preparer_statement_model_balanced.png, preparer_statement_model_greenfield.png, preparer_statement_model_flagged_unbalanced.png
A14: W2-03 | B14: W2 Financials | C14: Return metrics equity IRR, ROIC, payback, MOIC for base/upside/downside | D14: FIN-03 | E14: Must | F14: M | G14: S2 | H14: W2-01 | I14: Financials squad | J14: All three scenarios mandatory; downside required | K14: Done | L14: 5 | M14: code: server/config/returnMetrics.js (RETURN_SCENARIOS base/upside/downside, RETURN_METRICS equity_irr/roic/payback required + moic where-relevant, returnsFromFlatFields, evaluateReturnMetrics); server/config/intakeConfig.js flat capture fields (none required); server/gate.js evaluateGate return_metrics + GET /api/gate/fields returns config; server/config/siriusMemo.js resolveReturns + MOIC hurdle row; src/pages/SubmitOpportunity.jsx advisory 4c card (data-testid=returns-scenarios-card, returns-scenarios-status, returns-row-<metric>, returns-cell-<metric>-<scenario>, returns-scenarios-downside, returns-scenarios-flag/ok); SiriusMemoDialog.jsx memo-returns-table; server/config/mvpSeed.js complete set on full-pack fixtures + base-only on seed-below-floor. test: server/tests/returnMetrics.test.js (8 pass); server/tests/m2.test.js FIN-03 cases (config, complete, downside-missing); siriusMemo.test.js flat-field case. Evidence: docs/evidence/W2-03/preparer_returns_three_scenarios.png, preparer_returns_downside_missing.png, analyst_memo_returns_scenarios.png
A15: W2-04 | B15: W2 Financials | C15: Automatic hurdle table per scenario, admin-configurable + versioned | D15: FIN-04 | E15: Must | F15: M | G15: S2 | H15: W2-03, W2-05 | I15: Financials squad | J15: Meets/Does-not-meet per hurdle per scenario; values versioned | K15: Done | L15: 5 | M15: code: server/config/hurdleTable.js (HURDLE_TABLE_VERSION, HURDLE_META/HURDLE_DEFAULTS, hurdleThresholds resolving ROIC to WACC+spread, computeHurdles per-scenario with deal-level concentration/leverage, advisory below_hurdle/no_threshold flags); server/themes.js merges HURDLE_DEFAULTS into DEFAULT_THRESHOLDS + getHurdlePolicy + GET /api/themes/hurdles; server/gate.js hurdle_table on evaluateGate + versioned rows on GET /api/gate/fields; server/config/siriusMemo.js live thresholds + per-scenario Meets? + policy-version note in the page-4 returns table; src/pages/SubmitOpportunity.jsx advisory 4e card (data-testid=hurdle-table-card, hurdle-table-status, hurdle-row-<k>, hurdle-threshold-<k>, hurdle-cell-<k>-<s>, hurdle-passrate-<s>, hurdle-table-version, hurdle-table-flag/ok); leverage derived from a captured net-debt line via deriveFinancials. test: server/tests/hurdleTable.test.js (12 pass); server/tests/m2.test.js FIN-04 cases (config versioned, per-scenario verdicts, deal-level constants, below-hurdle flag, org policy); siriusMemo.test.js memo hurdle cases. Evidence: docs/evidence/W2-04/preparer_hurdle_table_per_scenario.png, preparer_hurdle_table_all_met.png, analyst_memo_hurdle_table.png
A16: W2-05 | B16: W2 Financials | C16: WACC input per entity (Sirius-set) + per-opportunity override with reason | D16: FIN-05 | E16: Must | F16: S | G16: S2 | I16: Financials squad | J16: Default by entity; override requires reason | K16: Done | L16: 2 | M16: code: server/config/wacc.js (WACC_DEFAULT_PCT env-overridable, WACC_OVERRIDE_FIELD/REASON_FIELD, WACC_OVERRIDE_REASON_MESSAGE, resolveWacc -> effective_wacc/source(entity_default|opportunity_override|system_default)/override_valid, meetsWaccSpread); server/db.js mandate_threshold.wacc_pct ALTER; server/themes.js DEFAULT_THRESHOLDS + getThresholds + upsertThresholds carry wacc_pct; server/gate.js resolveWacc on evaluateGate + wacc config on GET /api/gate/fields; server/config/intakeConfig.js wacc_override_pct + wacc_override_reason (not required); src/pages/ThemeAdmin.jsx Entity WACC threshold field; src/pages/SubmitOpportunity.jsx advisory 4d card (data-testid=wacc-card, wacc-status, wacc-effective, wacc-source, wacc-roic-summary, wacc-override-reason, wacc-flag); server/mvpSeed.js per-org entity WACC (Infinia 9, Finstreet 8.5, Sirius 7.5) merged onto operator thresholds; server/config/mvpSeed.js reasoned override on seed-theme-exception + reasonless override on seed-conflict. test: server/tests/wacc.test.js (7 pass); server/tests/m2.test.js FIN-05 cases (config, entity-default inheritance, reasoned override, reasonless flagged). Evidence: docs/evidence/W2-05/preparer_wacc_entity_default.png, preparer_wacc_override_with_reason.png, preparer_wacc_override_missing_reason.png
A17: W2-06 | B17: W2 Financials | C17: Sources and uses table with status, sources = uses validation, funding-hierarchy warning | D17: FIN-06 | E17: Must | F17: M | G17: S2 | I17: Financials squad | J17: Sources must equal uses; warning when Sirius capital used ahead of cheaper sources | K17: Done | L17: 5 | M17: code: server/config/sourcesUses.js (FUNDING_STATUSES secured/committed/indicative, SOURCE_ROWS subsidiary_accruals/subsidiary_debt/partner_co_investor/sirius_capital, USE_ROWS purchase_price/transaction_costs/working_capital/contingency, BALANCE_TOLERANCE_PCT env-overridable, evaluateSourcesUses -> rows with aed/%/status, totals, difference, balanced, sirius_ask_aed, hierarchy {order,violation,ahead_of}, flags [sources_not_uses|funding_hierarchy|invalid_status]); server/gate.js sources_uses on evaluateGate + config on GET /api/gate/fields; server/config/siriusMemo.js funding tables built from the plan (source row with AED mn/%/status + totals, uses + total, balance note); src/pages/SubmitOpportunity.jsx 5a card (data-testid=sources-uses-card, sources-uses-status, source-row-<k>, source-aed-<k>, source-pct-<k>, source-status-<k>, use-row-<k>, use-aed-<k>, sources-uses-total-sources, sources-uses-total-uses, sources-uses-difference, sources-uses-flag, sources-uses-hierarchy-flag, sources-uses-ok); SiriusMemoDialog.jsx memo-funding-tables. test: server/tests/sourcesUses.test.js (10 pass); server/tests/m2.test.js FIN-06 cases (config, balanced, imbalanced flag, hierarchy flag, cheaper-secured-first no flag). Evidence: docs/evidence/W2-06/preparer_sources_uses_balanced.png, preparer_sources_uses_hierarchy_flag.png, analyst_memo_sources_uses.png
A18: W2-07 | B18: W2 Financials | C18: Budget status with variance-memo enforcement on No | D18: FIN-07 | E18: Must | F18: S | G18: S2 | I18: Financials squad | J18: No makes variance memo upload mandatory | K18: Done | L18: 2 | M18: code: server/config/budgetStatus.js (BUDGET_FIELDS in_approved_budget/budget_status/budget_line_reference/variance_justification, VARIANCE_MEMO_KEY=budget_confirmation, BUDGET_STATUS_VALUES in_budget/variance_justified, evaluateBudgetStatus -> applies/answered/in_budget/off_budget/budget_status/line_reference/justification/variance_memo_required/variance_memo_present/satisfied, stops [budget_answer_required|variance_justification_required|variance_memo_required], flags [budget_line_missing]); server/gate.js budget_status on evaluateGate + off-budget variance memo pushed into missing + config on GET /api/gate/fields + submit-route 422 submit_blocked block; server/config/intakeConfig.js budget_line_reference + variance_justification (not required); server/config/siriusMemo.js budget note from the same evaluation; src/pages/SubmitOpportunity.jsx 5b card (data-testid=budget-status-card, budget-status-badge, budget-line-reference, budget-variance, budget-variance-memo, budget-status-flag, budget-status-line-flag, budget-status-ok). test: server/tests/budgetStatus.test.js (8 pass); server/tests/m2.test.js FIN-07 cases (config, in-budget satisfied, off-budget blocked + missing memo, off-budget satisfied with justification + memo). Evidence: docs/evidence/W2-07/preparer_budget_status_in_budget.png, preparer_budget_status_off_budget.png, analyst_memo_budget_status.png
A19: W2-08 | B19: W2 Financials | C19: Entry valuation & exit structured fields (EV, multiple, method, 3-5 comps, exit route) | D19: FIN-09 | E19: Must | F19: M | G19: S2 | I19: Financials squad | J19: Structured capture; comps 3-5 | K19: Done | L19: 5 | M19: code: server/config/valuation.js (VALUATION_BASIS ev/equity, VALUATION_METHODS trading_comps/precedent_transactions/dcf/asset_based/other, COMPARABLE_MIN=3/COMPARABLE_MAX=5, VALUATION_FIELDS basis/amount/multiple/method/comparables/exit_route/exit_timing/exit_multiple, evaluateValuation -> entry {amount,basis,basis_valid,multiple,method,method_valid,present,complete}, comparables[], comparable_count, comparables_ok, exit {route,timing,multiple,present,complete}, captured, complete, flags [entry_amount_missing|entry_basis_missing|entry_method_missing|comps_incomplete|comps_too_many|exit_incomplete], message); server/config/intakeConfig.js entry_valuation_basis + entry_valuation_method (selects) + exit_multiple (number), none required; server/gate.js valuation on evaluateGate + config on GET /api/gate/fields; server/config/siriusMemo.js Entry valuation & comparable set table (padded to >=3 rows) + entry-basis and exit notes; src/pages/SubmitOpportunity.jsx 4b card (data-testid=valuation-card, valuation-status, valuation-entry-basis/amount/multiple/method, valuation-comparable-row-<i>/name-<i>/metric-<i>/multiple-<i>, valuation-exit-route/timing/multiple, valuation-flag, valuation-ok) with the seven flat keys filtered out of the generic section loop; SiriusMemoDialog.jsx generic table testid (memo-valuation-table). test: server/tests/valuation.test.js (10 pass); server/tests/m2.test.js FIN-09 cases (config exposes fields + comparable bounds, complete capture no flags, below-minimum flagged not blocked). Evidence: docs/evidence/W2-08/preparer_valuation_complete.png, preparer_valuation_incomplete_flag.png, analyst_memo_valuation_table.png
A20: W2-09 | B20: W2 Financials | C20: Cross-border fields (FX, WHT, transfer pricing, repatriation), conditional on geography | D20: FIN-08 | E20: Should | F20: S | G20: S2 | I20: Financials squad | J20: Fields appear when target geography differs from home country | K20: Done | L20: 2 | M20: code: server/config/crossBorder.js (CROSS_BORDER_FIELDS fx/wht/transfer_pricing/repatriation, CROSS_BORDER_ITEMS in BRD order, canonicalCountry + isCrossBorder mapping free-text geography onto a country via GEOGRAPHY_TAGS so UAE==United Arab Emirates, evaluateCrossBorder(data,{homeCountry}) -> applies/target_country/home_country/items[{key,label,short,value,present}]/captured/total/complete/flags[<short>_missing]/message); server/gate.js cross_border on evaluateGate (home country via getOrganization(ownerOrg).geography) + config on GET /api/gate/fields; server/config/intakeConfig.js cross_border_fx/wht/transfer_pricing/repatriation (textareas, not required); server/config/siriusMemo.js Cross-border considerations table + target-vs-home note only when applies (homeCountry threaded through ctx); src/pages/SubmitOpportunity.jsx 4c card (data-testid=cross-border-card, cross-border-status, cross-border-fx/wht/transfer-pricing/repatriation, cross-border-flag, cross-border-ok) rendered only when the gate applies, four flat keys filtered out of the generic loop; fixture seed-cross-border (India target, UAE Infinia home). test: server/tests/crossBorder.test.js (10 pass); server/tests/m2.test.js FIN-08 cases (config exposes fields+items, same-country not applies, cross-country all-four complete, partial flagged not blocked). Evidence: docs/evidence/W2-09/preparer_cross_border_complete.png, preparer_cross_border_not_applicable.png, analyst_memo_cross_border.png
A21: W2-10 | B21: W2 Financials | C21: Per-opportunity FX rate capture attached to financial fields | D21: NFR-08 | E21: Must | F21: S | G21: S2 | H21: W2-01 | I21: Financials squad | J21: Currency/unit shown on every financial field; FX recorded | K21: Done | L21: 2 | M21: code: server/config/currency.js (BASE_CURRENCY AED, BASE_UNIT mn, REPORTING_CURRENCIES AED/USD, CURRENCY_FIELDS reporting_currency + fx_rate_usd_aed, normaliseCurrency defaults to AED, evaluateCurrency -> currency/unit/is_base/fx_rate/fx_required/fx_present/fx_valid/base_currency/label/rate_label/complete/flags[fx_rate_missing|fx_rate_invalid]/message, toBaseCurrency converts USD->AED at the recorded rate or null); server/gate.js currency on evaluateGate + config on GET /api/gate/fields; server/config/intakeConfig.js reporting_currency (select) + fx_rate_usd_aed (number), neither required; server/config/siriusMemo.js finTable headed "Financials (<label>)" with unit column = label + Reporting currency & units note; server/siriusMemoDocx.js + SiriusMemoDialog.jsx render the label; src/pages/SubmitOpportunity.jsx Reporting currency & FX rate card at the top of the financials section (data-testid=currency-card, currency-status, currency-select, currency-fx-rate, currency-unit-note, currency-flag, currency-ok), 4a heading reads the chosen currency + unit, rate field disabled on the base currency, two flat keys filtered out of the generic loop; fixtures seed-fx-usd (USD @ 3.6725) + seed-fx-missing (USD, no rate). test: server/tests/currency.test.js (8 pass); server/tests/m2.test.js NFR-08 cases (config exposes base currency + field names, default AED complete no flags, USD with rate complete, USD without rate flagged not blocked). Evidence: docs/evidence/W2-10/preparer_currency_complete_usd.png, preparer_currency_default_aed.png, preparer_currency_flag_missing_rate.png, analyst_memo_currency_label.png
A22: W3-01 | B22: W3 Screening | C22: Single screening panel aggregating eligibility, hard filters, hurdles, alignment, synergy/conflict, completeness | D22: SCR-01 | E22: Must | F22: L | G22: S3 | H22: W2-02, W2-04 | I22: Screening squad | J22: Runs within 15 min of submission; each check shows result, rationale, evidence ref | K22: Done | L22: 10 | M22: code: server/config/screeningPanel.js (SCREENING_CHECKS six BRD checks in order, SCREENING_SLA_MINUTES 15, advisory SCREENING_DISCLAIMER, evaluateScreeningPanel({gate,alignment,duplicates,conflict}) -> checks[{key,module,label,order,advisory,result pass|flag|fail|not_applicable,pending,status,rationale,evidence_refs,detail}] + summary{counts,blocking,flagged,advisory_open,recommended,complete} + complete/flags/message, composes the existing gate blocks (self_screen, below_floor, hurdle_table, statement_model, currency, missing, completeness) + alignment score, hard filters & synergy marked advisory, missing theme / unentered returns = pending not false verdict, never-rejects SCR-09); server/pipeline.js GET /opportunities/:id/screening (404/403 org-visibility, duplicates for cross-org readers only); src/api/client.js api.pipeline.screening(id); src/pages/ScreeningBoard.jsx screening panel at top of detail sheet (data-testid=screening-panel + screening-check-<key>) with result badges, advisory marker, evidence chips + i18n board.initialScreening. test: server/tests/screeningPanel.test.js (10 pass); server/tests/m3.test.js W3-01 cases (5 pass: panel shape + result/rationale/evidence per check + advisory disclaimer, submitted opportunity complete, stopped self-screen fails eligibility, sibling 403, missing 404). Evidence: docs/evidence/W3-01/analyst_screening_panel_overview.png, analyst_screening_panel_alignment_flag.png, analyst_screening_panel_conflict_signals.png
A23: W3-02 | B23: W3 Screening | C23: Gate 1 hard filters -> Recommended decline, reviewer confirm/override | D23: SCR-03 | E23: Must | F23: M | G23: S3 | H23: W3-01 | I23: Screening squad | J23: Failed filter sets Recommended decline with reason; system never rejects alone | K23: Done | L23: 5 | M23: code: server/config/hardFilters.js (HARD_FILTER_VERSION HF-01.1, HARD_FILTER_ITEMS five Standing filters in BRD order - designated_vertical / check_size / sanctions_export / structuring / portfolio_conflict, HARD_FILTER_FIELDS six manual inputs, HARD_FILTER_REVIEW_DECISIONS confirmed|overridden + REASON_MIN 10, evaluateHardFilters(data,{theme,thresholds}) -> items[{key,label,group,order,manual,status pass|fail|flag|not_evaluated,pending,rationale,evidence_refs,detail}]/failed[]/pending[]/recommended_outcome/recommended_reason/effective_outcome/review/awaiting_review/complete/flags/message, buildHardFilterReview validates a review and requires a written reason); server/config/intakeConfig.js six non-required hard-filter fields in the risks section (14-key required minimum unchanged); server/gate.js hard_filters on evaluateGate (effective theme resolved for the owner org) + config on GET /api/gate/fields + POST /opportunities/:id/hard-filter-review (write-org 403, 409 when nothing failed, decision persisted + audited hard_filter_<decision>) + GET /opportunities/:id/hard-filter-review/history; server/config/screeningPanel.js hard_filters check advisory:false reading the gate block (fail->Fail, flagged manual->Flag, else Pass); src/api/client.js gate.reviewHardFilter; src/pages/SubmitOpportunity.jsx 6a hard-filters card (hard-filters-card, hard-filter-<key>, hard-filter-sanctions/structuring/portfolio-conflict + notes + conflict-reviewer, hard-filters-outcome, hard-filters-decline); src/pages/ScreeningBoard.jsx reviewer confirm/override control (hard-filter-review, hard-filter-decision-confirmed/overridden, hard-filter-reason, hard-filter-submit). test: server/tests/hardFilters.test.js (17 pass); server/tests/screeningPanel.test.js (11 pass incl. failed filter -> Fail + recommended decline); server/tests/m3.test.js W3-02 cases (4 pass: five filters with outcomes, /fields config, failed filter -> recommended_decline + override needs reason + short reason 400, sibling 403 + clean deal 409). Evidence: docs/evidence/W3-02/preparer_hard_filters_form.png, analyst_hard_filters_recommended_decline.png, reviewer_hard_filters_review_override.png
A24: W3-03 | B24: W3 Screening | C24: Gate 1 soft filters scored 1-5 with proposed score + rationale | D24: SCR-04 | E24: Must | F24: M | G24: S3 | H24: W3-01 | I24: Screening squad | J24: Each soft filter scored; reviewer confirms | K24: Done | L24: 5 | M24: code: server/config/softFilters.js (SOFT_FILTER_VERSION SF-01.1, SOFT_FILTER_ITEMS three scored soft filters in BRD order - portfolio_adjacency / national_priorities / management_openness, SOFT_FILTER_FIELDS four manual inputs, SOFT_FILTER_SCALE 1-5, SOFT_FILTER_OUTCOMES strong|moderate|weak, UAE_PRIORITY_SECTORS, evaluateSoftFilters(data,{theme,portfolio,nationalPriorities}) -> items[{key,label,group,order,proposed_score,proposed_label,score,label_band,confirmed,adjusted,rationale,evidence_refs,detail}]/item_count/proposed_average/average/average_label/outcome/review/awaiting_review/complete/flags/message, buildSoftFilterReview validates a review and requires all three scores 1-5 plus a rationale >=10 chars); server/config/intakeConfig.js four non-required soft-filter fields in the risks section (14-key required minimum unchanged); server/gate.js soft_filters on evaluateGate (theme/portfolio/national-priorities inputs) + config on GET /api/gate/fields + POST /opportunities/:id/soft-filter-review (write-org 403, decision persisted + audited soft_filter_<decision>) + GET /opportunities/:id/soft-filter-review/history; server/config/screeningPanel.js soft_filters ride along as a section, not one of the six checks; src/api/client.js gate.reviewSoftFilter; src/pages/SubmitOpportunity.jsx 6b soft-filters card (soft-filters-card, soft-filter-<key>, soft-filter-management-openness + notes, soft-filters-outcome, soft-filters-scale); src/pages/ScreeningBoard.jsx reviewer confirm/adjust control (soft-filter-review, soft-filter-row-<key>, soft-filter-score-<key>-<n>, soft-filter-rationale-<key>, soft-filter-submit). test: server/tests/softFilters.test.js (10 pass); server/tests/screeningPanel.test.js (12 pass incl. soft filters ride-along section); server/tests/m3.test.js W3-03 cases (4 pass: three scored filters + proposed scores + awaiting_review, /fields config, short rationale 400 + bad score 400 + reasoned decision 200 confirms/adjusts + audit history + re-read persists, sibling 403). Evidence: docs/evidence/W3-03/preparer_soft_filters_form.png, analyst_soft_filters_scored_not_declined.png, reviewer_soft_filters_review_adjust.png
A25: W3-04 | B25: W3 Screening | C25: Disqualifier flags with named clear + reason | D25: SCR-05 | E25: Must | F25: M | G25: S3 | H25: W3-02 | I25: Screening squad | J25: Flag prominent on record and memo; clearing needs reviewer + reason | K25: Done | L25: 5 | M25: docs/evidence/W3-04/ - preparer form, analyst 2-open-flags, reviewer named clear; server/tests/disqualifiers.test.js 11 pass, m3 4 cases
A26: W3-05 | B26: W3 Screening | C26: Weighted 1-5 scorecard from Gate 2 criteria; weights sum 100%; >= 3.5 to proceed | D26: SCO-02 | E26: Must | F26: L | G26: S3 | H26: W3-03 | I26: Screening squad | J26: Weights validated to 100%; guide text per criterion; total/outcome auto | K26: Done | L26: 10 | M26: docs/evidence/W3-05/ - weighted summary, criteria scoring, CIO override below bar; server/tests/scorecard.test.js 12 pass, m3 3 cases
A27: W3-06 | B27: W3 Screening | C27: Two-lens floor (strategic vs financial sub-totals) | D27: SCO-04 | E27: Should | F27: M | G27: S3 | H27: W3-05 | I27: Screening squad | J27: Sub-totals shown; below floor if either under floor | K27: Done | L27: 5 | M27: docs/evidence/W3-06/
A28: W3-07 | B28: W3 Screening | C28: System-proposed scores per criterion (proposed + final stored; comment on adjustment) | D28: SCO-03 | E28: Should | F28: M | G28: S3 | H28: W3-05 | I28: Screening squad | J28: Both stored; comment required on adjustment | K28: Done | L28: 5 | M28: docs/evidence/W3-07/
A29: W3-08 | B29: W3 Screening | C29: Scorecard configuration admin (criteria, weights, thresholds, guide text), versioned | D29: SCO-05 | E29: Must | F29: M | G29: S3 | H29: W3-05 | I29: Screening squad | J29: Versioned + audited; historical scores not silently recalculated | K29: Done | L29: 5 | M29: docs/evidence/W3-08/
A30: W3-09 | B30: W3 Screening | C30: Overall quality score 0-100% with component breakdown and configurable bands | D30: SCO-01 | E30: Must | F30: M | G30: S3 | H30: W3-05 | I30: Screening squad | J30: Breakdown shown; advisory only; bands configurable | K30: Done | L30: 5 | M30: docs/evidence/W3-09/
A31: W3-10 | B31: W3 Screening | C31: Portfolio conflict & concentration check against register | D31: SCR-07 | E31: Should | F31: M | G31: S3 | H31: W4-01 | I31: Screening squad | J31: Conflict flags with affected company; concentration % where data exists | K31: Done | L31: 5 | M31: docs/evidence/W3-10/
A32: W3-11 | B32: W3 Screening | C32: Synergy identification against portfolio register | D32: SCR-06 | E32: Should | F32: M | G32: S3 | H32: W4-01 | I32: Screening squad | J32: Top synergies listed; marked requires operating-company sign-off | K32: Done | L32: 5 | M32: docs/evidence/W3-11/
A33: W3-12 | B33: W3 Screening | C33: Sanctions / adverse media manual confirmation field + evidence upload | D33: SCR-08 | E33: Should | F33: S | G33: S3 | I33: Screening squad | J33: Confirmation field with evidence on record | K33: Done | L33: 2 | M33: docs/evidence/W3-12/
A34: W3-13 | B34: W3 Screening | C34: Theme alignment document-passage citation (rationale quotes source doc) | D34: SCR-02 | E34: Must | F34: M | G34: S3 | H34: W4-02 | I34: Screening squad | J34: Per-dimension Aligned/Partly/Not aligned with rationale citing source passage | K34: Done | L34: 5 | M34: docs/evidence/W3-13/
A35: W4-01 | B35: W4 Entity | C35: Portfolio register seeded from BRD list with cluster/sector/geography/capability tags | D35: ENT-04 | E35: Must | F35: M | G35: S4 | I35: Data squad | J35: Register loadable from template; each record has sector/geo/capability tags | K35: Done | L35: 5 | M35: docs/evidence/W4-01/
A36: W4-02 | B36: W4 Entity | C36: Strategy document upload + indexing feeding the alignment engine within 10 min | D36: ENT-02 | E36: Must | F36: M | G36: S4 | I36: Data squad | J36: PDF/DOCX/PPTX indexed and available to alignment | K36: Done | L36: 5 | M36: docs/evidence/W4-02/
A37: W4-03 | B37: W4 Entity | C37: Versioned entity strategy profile; version recorded per screening | D37: ENT-01 | E37: Must | F37: M | G37: S4 | H37: W4-02 | I37: Data squad | J37: Profile versioned; version used recorded per screening | K37: Done | L37: 5 | M37: docs/evidence/W4-03/
A38: W4-04 | B38: W4 Entity | C38: Versioned Sirius mandate admin-editable | D38: ENT-03 | E38: Must | F38: S | G38: S4 | I38: Data squad | J38: Changes versioned + audited | K38: Done | L38: 2 | M38: docs/evidence/W4-04/
A39: W5-01 | B39: W5 Documents | C39: Checklist generation by type/stage/flags with mandatory/conditional/optional, admin-maintainable | D39: DOC-01 | E39: Must | F39: M | G39: S4 | H39: W1-03 | I39: Intake squad | J39: Checklist updates as answers change; admin edits without code | K39: Done | L39: 5 | M39: docs/evidence/W5-01/
A40: W5-02 | B40: W5 Documents | C40: Version history + virus scan on upload; 50 MB limit, PDF/DOCX/XLSX/PPTX | D40: DOC-02 | E40: Must | F40: M | G40: S4 | I40: Intake squad | J40: Previous versions retained; scan on upload | K40: Done | L40: 5 | M40: docs/evidence/W5-02/
...

Sheet Slices
A1: Slice | B1: Weeks | C1: Outcome | D1: Scope | E1: Exit criteria
A2: S0 | B2: W0 | C2: Reconcile & freeze | D2: BRD-to-plan reconciliation signed; backlog of record approved | E2: Plan signed; scope (62 Must + 20 Should) frozen
A3: S1 | B3: W1-W3 | C3: Intake governance | D3: Self-screen, below-floor exception, 6-section form, 10-gate checklist, accretion, greenfield, CEO/CFO attestation, withdraw, duplicate warning | E3: INT-02/03/06/07/08/09/10/13 pass; J1/J2/J3 green
A4: S2 | B4: W3-W6 | C4: Financials & returns | D4: Financial summary, 3-statement check, 3-scenario returns, hurdle table, WACC, sources/uses, budget, valuation/exit, cross-border, FX | E4: FIN-01..FIN-10 pass
A5: S3 | B5: W5-W8 | C5: Screening & scorecard | D5: Screening panel, hard/soft filters, disqualifiers, weighted scorecard + config, quality score, two-lens floor, proposed scores, conflict/synergy, sanctions field, alignment citation | E5: SCR-01..SCR-09, SCO-01..SCO-05 pass
A6: S4 | B6: W6-W8 | C6: Entity, docs & templates | D6: Portfolio register, strategy indexing, versioned profile/mandate, type-driven checklist, versioned uploads + scan, sufficiency check, data-point mapping, templates | E6: ENT-01..04, DOC-01..06 pass
A7: S5 | B7: W8-W10 | C7: Governance & audit hardening | D7: Reason codes, DoA, related-party overlay, internal/shared comments, hash-chained audit, presentation scheduling, notification frequency | E7: WF-05/06/07/08, AUD-01/03, NTF-01 pass; J7 green
A8: S6 | B8: W9-W11 | C8: Reporting & output | D8: IHC weekly report, pipeline filters, funnel/cycle metrics, 6-page pack export, QR verification | E8: DSH-01/03/04, OUT-02/03 pass
A9: S7 | B9: W10-W12 | C9: Platform, auth & config | D9: SSO/MFA, i18n completion, unified admin config, data-room link, bulk import, user-admin hardening | E9: PLT-04/05/06, ADM-01, INTG-01/03 pass
A10: S8 | B10: W12-W13 | C10: Hardening & NFR | D10: AI governance, security scan, residency, performance, backup, browser SIT, usability | E10: NFR-01..NFR-07 pass
A11: S9 | B11: W13-W14 | C11: UAT & sign-off | D11: Full-persona UAT on expanded scope; defect triage | E11: DoD met; Sirius signs off
A12: S10 | B12: W14-W15 | C12: Pilot rollout | D12: Pilot subsidiary live; first cluster onboarded | E12: Pilot submitting in-portal

Sheet Open Decisions
A1: # | B1: Type | C1: Item | D1: Owner | E1: Status
A2: Q1 | B2: Decision | C2: Identity provider for PLT-04 (Entra ID?) and whether subsidiaries share the tenant | D2: Sirius | E2: Open
A3: Q2 | B3: Decision | C3: Confirm scorecard weight set and score bands (SCO-01/02/05) | D3: Sirius | E3: Open
